2024-02-28 16:11:21,357 INFO    StreamThr :1223986 [internal.py:wandb_internal():86] W&B internal server running at pid: 1223986, started at: 2024-02-28 16:11:21.355810
2024-02-28 16:11:21,359 DEBUG   HandlerThread:1223986 [handler.py:handle_request():146] handle_request: status
2024-02-28 16:11:21,378 INFO    WriterThread:1223986 [datastore.py:open_for_write():85] open: /volumes1/xai_cl/multimodal_cl/nie_continual_learning/mammoth/wandb/run-20240228_161121-7k1c9254/run-7k1c9254.wandb
2024-02-28 16:11:21,378 DEBUG   SenderThread:1223986 [sender.py:send():382] send: header
2024-02-28 16:11:21,417 DEBUG   SenderThread:1223986 [sender.py:send():382] send: run
2024-02-28 16:11:21,789 ERROR   SenderThread:1223986 [internal_api.py:execute():373] 404 response executing GraphQL.
2024-02-28 16:11:21,789 ERROR   SenderThread:1223986 [internal_api.py:execute():374] {"errors":[{"message":"project not found","path":["upsertBucket"]}],"data":{"upsertBucket":null}}
2024-02-28 16:11:21,790 ERROR   SenderThread:1223986 [sender.py:send_run():987] It appears that you do not have permission to access the requested resource. Please reach out to the project owner to grant you access. If you have the correct permissions, verify that there are no issues with your networking setup.(Error 404: Not Found)
Traceback (most recent call last):
  File "/volumes2/anaconda3/envs/lang/lib/python3.10/site-packages/wandb/sdk/lib/retry.py", line 131, in __call__
    result = self._call_fn(*args, **kwargs)
  File "/volumes2/anaconda3/envs/lang/lib/python3.10/site-packages/wandb/sdk/internal/internal_api.py", line 369, in execute
    return self.client.execute(*args, **kwargs)  # type: ignore
  File "/volumes2/anaconda3/envs/lang/lib/python3.10/site-packages/wandb/vendor/gql-0.2.0/wandb_gql/client.py", line 52, in execute
    result = self._get_result(document, *args, **kwargs)
  File "/volumes2/anaconda3/envs/lang/lib/python3.10/site-packages/wandb/vendor/gql-0.2.0/wandb_gql/client.py", line 60, in _get_result
    return self.transport.execute(document, *args, **kwargs)
  File "/volumes2/anaconda3/envs/lang/lib/python3.10/site-packages/wandb/sdk/lib/gql_request.py", line 59, in execute
    request.raise_for_status()
  File "/volumes2/anaconda3/envs/lang/lib/python3.10/site-packages/requests/models.py", line 1021, in raise_for_status
    raise HTTPError(http_error_msg, response=self)
requests.exceptions.HTTPError: 404 Client Error: Not Found for url: https://api.wandb.ai/graphql

During handling of the above exception, another exception occurred:

Traceback (most recent call last):
  File "/volumes2/anaconda3/envs/lang/lib/python3.10/site-packages/wandb/sdk/internal/sender.py", line 985, in send_run
    self._init_run(run, config_value_dict)
  File "/volumes2/anaconda3/envs/lang/lib/python3.10/site-packages/wandb/sdk/internal/sender.py", line 1027, in _init_run
    server_run, inserted, server_messages = self._api.upsert_run(
  File "/volumes2/anaconda3/envs/lang/lib/python3.10/site-packages/wandb/apis/normalize.py", line 73, in wrapper
    raise err
  File "/volumes2/anaconda3/envs/lang/lib/python3.10/site-packages/wandb/apis/normalize.py", line 41, in wrapper
    return func(*args, **kwargs)
  File "/volumes2/anaconda3/envs/lang/lib/python3.10/site-packages/wandb/sdk/internal/internal_api.py", line 2212, in upsert_run
    response = self.gql(
  File "/volumes2/anaconda3/envs/lang/lib/python3.10/site-packages/wandb/sdk/internal/internal_api.py", line 341, in gql
    ret = self._retry_gql(
  File "/volumes2/anaconda3/envs/lang/lib/python3.10/site-packages/wandb/sdk/lib/retry.py", line 147, in __call__
    retry_timedelta_triggered = check_retry_fn(e)
  File "/volumes2/anaconda3/envs/lang/lib/python3.10/site-packages/wandb/util.py", line 965, in check_retry_fn
    return fallback_retry_fn(e)
  File "/volumes2/anaconda3/envs/lang/lib/python3.10/site-packages/wandb/util.py", line 907, in no_retry_auth
    raise CommError(
wandb.errors.CommError: It appears that you do not have permission to access the requested resource. Please reach out to the project owner to grant you access. If you have the correct permissions, verify that there are no issues with your networking setup.(Error 404: Not Found)
2024-02-28 16:11:26,844 DEBUG   HandlerThread:1223986 [handler.py:handle_request():146] handle_request: status_report
2024-02-28 16:11:31,844 DEBUG   HandlerThread:1223986 [handler.py:handle_request():146] handle_request: status_report
2024-02-28 16:11:36,846 DEBUG   HandlerThread:1223986 [handler.py:handle_request():146] handle_request: status_report
2024-02-28 16:11:41,848 DEBUG   HandlerThread:1223986 [handler.py:handle_request():146] handle_request: status_report
2024-02-28 16:11:46,849 DEBUG   HandlerThread:1223986 [handler.py:handle_request():146] handle_request: status_report
2024-02-28 16:11:51,851 DEBUG   HandlerThread:1223986 [handler.py:handle_request():146] handle_request: status_report
2024-02-28 16:11:56,852 DEBUG   HandlerThread:1223986 [handler.py:handle_request():146] handle_request: status_report
2024-02-28 16:12:01,854 DEBUG   HandlerThread:1223986 [handler.py:handle_request():146] handle_request: status_report
