2024-02-28 16:11:21,341 INFO    MainThread:1223707 [wandb_setup.py:_flush():76] Current SDK version is 0.16.1
2024-02-28 16:11:21,342 INFO    MainThread:1223707 [wandb_setup.py:_flush():76] Configure stats pid to 1223707
2024-02-28 16:11:21,342 INFO    MainThread:1223707 [wandb_setup.py:_flush():76] Loading settings from /data/users/shruthi.gowda/.config/wandb/settings
2024-02-28 16:11:21,342 INFO    MainThread:1223707 [wandb_setup.py:_flush():76] Loading settings from /volumes1/xai_cl/multimodal_cl/nie_continual_learning/mammoth/wandb/settings
2024-02-28 16:11:21,342 INFO    MainThread:1223707 [wandb_setup.py:_flush():76] Loading settings from environment variables: {}
2024-02-28 16:11:21,343 INFO    MainThread:1223707 [wandb_setup.py:_flush():76] Applying setup settings: {'_disable_service': False}
2024-02-28 16:11:21,343 INFO    MainThread:1223707 [wandb_setup.py:_flush():76] Inferring run settings from compute environment: {'program_relpath': 'mammoth/main.py', 'program_abspath': '/volumes1/xai_cl/multimodal_cl/nie_continual_learning/mammoth/main.py', 'program': '/volumes1/xai_cl/multimodal_cl/nie_continual_learning/mammoth/main.py'}
2024-02-28 16:11:21,343 INFO    MainThread:1223707 [wandb_init.py:_log_setup():524] Logging user logs to /volumes1/xai_cl/multimodal_cl/nie_continual_learning/mammoth/wandb/run-20240228_161121-7k1c9254/logs/debug.log
2024-02-28 16:11:21,343 INFO    MainThread:1223707 [wandb_init.py:_log_setup():525] Logging internal logs to /volumes1/xai_cl/multimodal_cl/nie_continual_learning/mammoth/wandb/run-20240228_161121-7k1c9254/logs/debug-internal.log
2024-02-28 16:11:21,343 INFO    MainThread:1223707 [wandb_init.py:init():564] calling init triggers
2024-02-28 16:11:21,343 INFO    MainThread:1223707 [wandb_init.py:init():571] wandb.init called with sweep_config: {}
config: {'seed': None, 'notes': None, 'non_verbose': 0, 'disable_log': 0, 'tensorboard': 0, 'validation': 0, 'ignore_other_metrics': 0, 'debug_mode': 0, 'nowand': 0, 'wandb_entity': 'regaz', 'wandb_project': 'mammoth', 'experiment_id': '20240228_161114_188351', 'dataset_dir': 'data', 'output_dir': 'experiments', 'dataset': 'seq-cifar10', 'mnist_seed': 0, 'n_tasks_cif': 5, 'n_tasks_mnist': 20, 'deg_inc': 8, 'model': 'vl_er', 'lr': 0.1, 'optim_wd': 0.0, 'optim_mom': 0.0, 'optim_nesterov': 0, 'n_epochs': 50, 'batch_size': 32, 'buffer_size': 200, 'minibatch_size': 32, 'aux': 'shape', 'img_size': 32, 'loss_type': ['l2'], 'loss_wt': [1.0, 1.0, 1.0, 1.0], 'dir_aux': False, 'buf_aux': False, 'aug_prob': 0.0, 'data_combine': False, 'conf_jobnum': '35345948-9c39-4aa3-808d-3692708c6686', 'conf_timestamp': '2024-02-28 16:11:14.190051', 'conf_host': 'nides068'}
2024-02-28 16:11:21,343 INFO    MainThread:1223707 [wandb_init.py:init():614] starting backend
2024-02-28 16:11:21,343 INFO    MainThread:1223707 [wandb_init.py:init():618] setting up manager
2024-02-28 16:11:21,353 INFO    MainThread:1223707 [backend.py:_multiprocessing_setup():105] multiprocessing start_methods=fork,spawn,forkserver, using: spawn
2024-02-28 16:11:21,355 INFO    MainThread:1223707 [wandb_init.py:init():624] backend started and connected
2024-02-28 16:11:21,377 INFO    MainThread:1223707 [wandb_init.py:init():716] updated telemetry
2024-02-28 16:11:21,409 INFO    MainThread:1223707 [wandb_init.py:init():749] communicating run to backend with 90.0 second timeout
2024-02-28 16:11:21,843 ERROR   MainThread:1223707 [wandb_init.py:init():775] encountered error: It appears that you do not have permission to access the requested resource. Please reach out to the project owner to grant you access. If you have the correct permissions, verify that there are no issues with your networking setup.(Error 404: Not Found)
2024-02-28 16:11:21,990 ERROR   MainThread:1223707 [wandb_init.py:init():1188] It appears that you do not have permission to access the requested resource. Please reach out to the project owner to grant you access. If you have the correct permissions, verify that there are no issues with your networking setup.(Error 404: Not Found)
Traceback (most recent call last):
  File "/volumes2/anaconda3/envs/lang/lib/python3.10/site-packages/wandb/sdk/wandb_init.py", line 1170, in init
    run = wi.init()
  File "/volumes2/anaconda3/envs/lang/lib/python3.10/site-packages/wandb/sdk/wandb_init.py", line 781, in init
    raise error
wandb.errors.CommError: It appears that you do not have permission to access the requested resource. Please reach out to the project owner to grant you access. If you have the correct permissions, verify that there are no issues with your networking setup.(Error 404: Not Found)
